Watching for file changes with StatReloader
Watching for file changes with StatReloader
"GET /summit HTTP/1.1" 301 0
Internal Server Error: /summit/
Traceback (most recent call last):
  File "/home/ubuntu/.local/lib/python3.10/site-packages/django/core/handlers/exception.py", line 56, in inner
    response = get_response(request)
  File "/home/ubuntu/.local/lib/python3.10/site-packages/django/utils/deprecation.py", line 138, in __call__
    response = self.process_response(request, response)
  File "/home/ubuntu/.local/lib/python3.10/site-packages/django/middleware/clickjacking.py", line 27, in process_response
    if response.get("X-Frame-Options") is not None:
AttributeError: 'SummitData' object has no attribute 'get'
"GET /summit/ HTTP/1.1" 500 145
Not Found: /favicon.ico
"GET /favicon.ico HTTP/1.1" 404 179
/home/ubuntu/OneForAll/website/summit/urls.py changed, reloading.
Watching for file changes with StatReloader
"GET /summit/ HTTP/1.1" 200 3327
"POST /summit/ HTTP/1.1" 302 0
Internal Server Error: /summit/list
Traceback (most recent call last):
  File "/home/ubuntu/.local/lib/python3.10/site-packages/django/core/handlers/exception.py", line 56, in inner
    response = get_response(request)
  File "/home/ubuntu/.local/lib/python3.10/site-packages/django/core/handlers/base.py", line 197, in _get_response
    response = wrapped_callback(request, *callback_args, **callback_kwargs)
  File "/home/ubuntu/.local/lib/python3.10/site-packages/django/contrib/auth/decorators.py", line 23, in _wrapped_view
    return view_func(request, *args, **kwargs)
TypeError: View.__init__() takes 1 positional argument but 2 were given
"GET /summit/list HTTP/1.1" 500 145
/home/ubuntu/OneForAll/website/summit/models.py changed, reloading.
Watching for file changes with StatReloader
"GET /summit/ HTTP/1.1" 200 3327
/home/ubuntu/OneForAll/website/summit/urls.py changed, reloading.
Watching for file changes with StatReloader
/home/ubuntu/OneForAll/website/summit/views.py changed, reloading.
Watching for file changes with StatReloader
/home/ubuntu/OneForAll/website/summit/views.py changed, reloading.
Watching for file changes with StatReloader
/home/ubuntu/OneForAll/website/summit/urls.py changed, reloading.
Watching for file changes with StatReloader
/home/ubuntu/OneForAll/website/summit/views.py changed, reloading.
Watching for file changes with StatReloader
/home/ubuntu/OneForAll/website/summit/urls.py changed, reloading.
Watching for file changes with StatReloader
Internal Server Error: /summit/
Traceback (most recent call last):
  File "/home/ubuntu/.local/lib/python3.10/site-packages/django/template/backends/django.py", line 61, in render
    return self.template.render(context)
  File "/home/ubuntu/.local/lib/python3.10/site-packages/django/template/base.py", line 175, in render
    return self._render(context)
  File "/home/ubuntu/.local/lib/python3.10/site-packages/django/template/base.py", line 167, in _render
    return self.nodelist.render(context)
  File "/home/ubuntu/.local/lib/python3.10/site-packages/django/template/base.py", line 1005, in render
    return SafeString("".join([node.render_annotated(context) for node in self]))
  File "/home/ubuntu/.local/lib/python3.10/site-packages/django/template/base.py", line 1005, in <listcomp>
    return SafeString("".join([node.render_annotated(context) for node in self]))
  File "/home/ubuntu/.local/lib/python3.10/site-packages/django/template/base.py", line 966, in render_annotated
    return self.render(context)
  File "/home/ubuntu/.local/lib/python3.10/site-packages/django/template/loader_tags.py", line 132, in render
    compiled_parent = self.get_parent(context)
  File "/home/ubuntu/.local/lib/python3.10/site-packages/django/template/loader_tags.py", line 129, in get_parent
    return self.find_template(parent, context)
  File "/home/ubuntu/.local/lib/python3.10/site-packages/django/template/loader_tags.py", line 107, in find_template
    template, origin = context.template.engine.find_template(
  File "/home/ubuntu/.local/lib/python3.10/site-packages/django/template/engine.py", line 161, in find_template
    raise TemplateDoesNotExist(name, tried=tried)
django.template.exceptions.TemplateDoesNotExist: base.html

The above exception was the direct cause of the following exception:

Traceback (most recent call last):
  File "/home/ubuntu/.local/lib/python3.10/site-packages/django/core/handlers/exception.py", line 56, in inner
    response = get_response(request)
  File "/home/ubuntu/.local/lib/python3.10/site-packages/django/core/handlers/base.py", line 197, in _get_response
    response = wrapped_callback(request, *callback_args, **callback_kwargs)
  File "/home/ubuntu/.local/lib/python3.10/site-packages/django/contrib/auth/decorators.py", line 23, in _wrapped_view
    return view_func(request, *args, **kwargs)
  File "/home/ubuntu/OneForAll/website/summit/views.py", line 31, in summit_form
    return render(request, 'summit/form.html', context)
  File "/home/ubuntu/.local/lib/python3.10/site-packages/django/shortcuts.py", line 24, in render
    content = loader.render_to_string(template_name, context, request, using=using)
  File "/home/ubuntu/.local/lib/python3.10/site-packages/django/template/loader.py", line 62, in render_to_string
    return template.render(context, request)
  File "/home/ubuntu/.local/lib/python3.10/site-packages/django/template/backends/django.py", line 63, in render
    reraise(exc, self.backend)
  File "/home/ubuntu/.local/lib/python3.10/site-packages/django/template/backends/django.py", line 84, in reraise
    raise new from exc
django.template.exceptions.TemplateDoesNotExist: base.html
"GET /summit/ HTTP/1.1" 500 145
"GET /summit/ HTTP/1.1" 200 3355
"POST /summit/ HTTP/1.1" 302 0
Internal Server Error: /summit/list
Traceback (most recent call last):
  File "/home/ubuntu/.local/lib/python3.10/site-packages/django/core/handlers/exception.py", line 56, in inner
    response = get_response(request)
  File "/home/ubuntu/.local/lib/python3.10/site-packages/django/core/handlers/base.py", line 197, in _get_response
    response = wrapped_callback(request, *callback_args, **callback_kwargs)
  File "/home/ubuntu/.local/lib/python3.10/site-packages/django/contrib/auth/decorators.py", line 23, in _wrapped_view
    return view_func(request, *args, **kwargs)
TypeError: View.__init__() takes 1 positional argument but 2 were given
"GET /summit/list HTTP/1.1" 500 145
/home/ubuntu/OneForAll/website/summit/views.py changed, reloading.
Watching for file changes with StatReloader
/home/ubuntu/OneForAll/website/summit/urls.py changed, reloading.
Watching for file changes with StatReloader
Internal Server Error: /summit/list
Traceback (most recent call last):
  File "/home/ubuntu/.local/lib/python3.10/site-packages/django/core/handlers/exception.py", line 56, in inner
    response = get_response(request)
  File "/home/ubuntu/.local/lib/python3.10/site-packages/django/core/handlers/base.py", line 197, in _get_response
    response = wrapped_callback(request, *callback_args, **callback_kwargs)
  File "/home/ubuntu/.local/lib/python3.10/site-packages/django/contrib/auth/decorators.py", line 23, in _wrapped_view
    return view_func(request, *args, **kwargs)
TypeError: View.__init__() takes 1 positional argument but 2 were given
"GET /summit/list HTTP/1.1" 500 145
/home/ubuntu/OneForAll/website/summit/views.py changed, reloading.
Watching for file changes with StatReloader
/home/ubuntu/OneForAll/website/summit/urls.py changed, reloading.
Watching for file changes with StatReloader
/home/ubuntu/OneForAll/website/summit/urls.py changed, reloading.
Watching for file changes with StatReloader
/home/ubuntu/OneForAll/website/summit/urls.py changed, reloading.
Watching for file changes with StatReloader
/home/ubuntu/OneForAll/website/summit/urls.py changed, reloading.
Watching for file changes with StatReloader
"GET /summit/list HTTP/1.1" 301 0
Internal Server Error: /summit/list/
Traceback (most recent call last):
  File "/home/ubuntu/.local/lib/python3.10/site-packages/django/core/handlers/exception.py", line 56, in inner
    response = get_response(request)
  File "/home/ubuntu/.local/lib/python3.10/site-packages/django/core/handlers/base.py", line 197, in _get_response
    response = wrapped_callback(request, *callback_args, **callback_kwargs)
  File "/home/ubuntu/.local/lib/python3.10/site-packages/django/contrib/auth/decorators.py", line 23, in _wrapped_view
    return view_func(request, *args, **kwargs)
TypeError: View.__init__() takes 1 positional argument but 2 were given
"GET /summit/list/ HTTP/1.1" 500 145
/home/ubuntu/OneForAll/website/summit/views.py changed, reloading.
Watching for file changes with StatReloader
/home/ubuntu/OneForAll/website/summit/urls.py changed, reloading.
Watching for file changes with StatReloader
Internal Server Error: /summit/list/
Traceback (most recent call last):
  File "/home/ubuntu/.local/lib/python3.10/site-packages/django/template/backends/django.py", line 61, in render
    return self.template.render(context)
  File "/home/ubuntu/.local/lib/python3.10/site-packages/django/template/base.py", line 175, in render
    return self._render(context)
  File "/home/ubuntu/.local/lib/python3.10/site-packages/django/template/base.py", line 167, in _render
    return self.nodelist.render(context)
  File "/home/ubuntu/.local/lib/python3.10/site-packages/django/template/base.py", line 1005, in render
    return SafeString("".join([node.render_annotated(context) for node in self]))
  File "/home/ubuntu/.local/lib/python3.10/site-packages/django/template/base.py", line 1005, in <listcomp>
    return SafeString("".join([node.render_annotated(context) for node in self]))
  File "/home/ubuntu/.local/lib/python3.10/site-packages/django/template/base.py", line 966, in render_annotated
    return self.render(context)
  File "/home/ubuntu/.local/lib/python3.10/site-packages/django/template/loader_tags.py", line 132, in render
    compiled_parent = self.get_parent(context)
  File "/home/ubuntu/.local/lib/python3.10/site-packages/django/template/loader_tags.py", line 129, in get_parent
    return self.find_template(parent, context)
  File "/home/ubuntu/.local/lib/python3.10/site-packages/django/template/loader_tags.py", line 107, in find_template
    template, origin = context.template.engine.find_template(
  File "/home/ubuntu/.local/lib/python3.10/site-packages/django/template/engine.py", line 161, in find_template
    raise TemplateDoesNotExist(name, tried=tried)
django.template.exceptions.TemplateDoesNotExist: base.html

The above exception was the direct cause of the following exception:

Traceback (most recent call last):
  File "/home/ubuntu/.local/lib/python3.10/site-packages/django/core/handlers/exception.py", line 56, in inner
    response = get_response(request)
  File "/home/ubuntu/.local/lib/python3.10/site-packages/django/core/handlers/base.py", line 220, in _get_response
    response = response.render()
  File "/home/ubuntu/.local/lib/python3.10/site-packages/django/template/response.py", line 114, in render
    self.content = self.rendered_content
  File "/home/ubuntu/.local/lib/python3.10/site-packages/django/template/response.py", line 92, in rendered_content
    return template.render(context, self._request)
  File "/home/ubuntu/.local/lib/python3.10/site-packages/django/template/backends/django.py", line 63, in render
    reraise(exc, self.backend)
  File "/home/ubuntu/.local/lib/python3.10/site-packages/django/template/backends/django.py", line 84, in reraise
    raise new from exc
django.template.exceptions.TemplateDoesNotExist: base.html
"GET /summit/list/ HTTP/1.1" 500 145
Internal Server Error: /summit/list/
Traceback (most recent call last):
  File "/home/ubuntu/.local/lib/python3.10/site-packages/django/core/handlers/exception.py", line 56, in inner
    response = get_response(request)
  File "/home/ubuntu/.local/lib/python3.10/site-packages/django/core/handlers/base.py", line 220, in _get_response
    response = response.render()
  File "/home/ubuntu/.local/lib/python3.10/site-packages/django/template/response.py", line 114, in render
    self.content = self.rendered_content
  File "/home/ubuntu/.local/lib/python3.10/site-packages/django/template/response.py", line 92, in rendered_content
    return template.render(context, self._request)
  File "/home/ubuntu/.local/lib/python3.10/site-packages/django/template/backends/django.py", line 61, in render
    return self.template.render(context)
  File "/home/ubuntu/.local/lib/python3.10/site-packages/django/template/base.py", line 175, in render
    return self._render(context)
  File "/home/ubuntu/.local/lib/python3.10/site-packages/django/template/base.py", line 167, in _render
    return self.nodelist.render(context)
  File "/home/ubuntu/.local/lib/python3.10/site-packages/django/template/base.py", line 1005, in render
    return SafeString("".join([node.render_annotated(context) for node in self]))
  File "/home/ubuntu/.local/lib/python3.10/site-packages/django/template/base.py", line 1005, in <listcomp>
    return SafeString("".join([node.render_annotated(context) for node in self]))
  File "/home/ubuntu/.local/lib/python3.10/site-packages/django/template/base.py", line 966, in render_annotated
    return self.render(context)
  File "/home/ubuntu/.local/lib/python3.10/site-packages/django/template/loader_tags.py", line 157, in render
    return compiled_parent._render(context)
  File "/home/ubuntu/.local/lib/python3.10/site-packages/django/template/base.py", line 167, in _render
    return self.nodelist.render(context)
  File "/home/ubuntu/.local/lib/python3.10/site-packages/django/template/base.py", line 1005, in render
    return SafeString("".join([node.render_annotated(context) for node in self]))
  File "/home/ubuntu/.local/lib/python3.10/site-packages/django/template/base.py", line 1005, in <listcomp>
    return SafeString("".join([node.render_annotated(context) for node in self]))
  File "/home/ubuntu/.local/lib/python3.10/site-packages/django/template/base.py", line 966, in render_annotated
    return self.render(context)
  File "/home/ubuntu/.local/lib/python3.10/site-packages/django/template/loader_tags.py", line 63, in render
    result = block.nodelist.render(context)
  File "/home/ubuntu/.local/lib/python3.10/site-packages/django/template/base.py", line 1005, in render
    return SafeString("".join([node.render_annotated(context) for node in self]))
  File "/home/ubuntu/.local/lib/python3.10/site-packages/django/template/base.py", line 1005, in <listcomp>
    return SafeString("".join([node.render_annotated(context) for node in self]))
  File "/home/ubuntu/.local/lib/python3.10/site-packages/django/template/base.py", line 966, in render_annotated
    return self.render(context)
  File "/home/ubuntu/.local/lib/python3.10/site-packages/django/template/defaulttags.py", line 238, in render
    nodelist.append(node.render_annotated(context))
  File "/home/ubuntu/.local/lib/python3.10/site-packages/django/template/base.py", line 966, in render_annotated
    return self.render(context)
  File "/home/ubuntu/.local/lib/python3.10/site-packages/django/template/defaulttags.py", line 471, in render
    url = reverse(view_name, args=args, kwargs=kwargs, current_app=current_app)
  File "/home/ubuntu/.local/lib/python3.10/site-packages/django/urls/base.py", line 88, in reverse
    return resolver._reverse_with_prefix(view, prefix, *args, **kwargs)
  File "/home/ubuntu/.local/lib/python3.10/site-packages/django/urls/resolvers.py", line 828, in _reverse_with_prefix
    raise NoReverseMatch(msg)
django.urls.exceptions.NoReverseMatch: Reverse for 'task-update' not found. 'task-update' is not a valid view function or pattern name.
"GET /summit/list/ HTTP/1.1" 500 145
"GET /summit/list/ HTTP/1.1" 200 3316
"GET /logout HTTP/1.1" 301 0
"GET /logout/ HTTP/1.1" 302 0
"GET /login HTTP/1.1" 301 0
"GET /login/ HTTP/1.1" 200 2845
"POST /login/ HTTP/1.1" 200 3033
"POST /login/ HTTP/1.1" 200 3033
"GET /sign-up HTTP/1.1" 200 3907
"POST /sign-up HTTP/1.1" 200 4196
"POST /sign-up HTTP/1.1" 200 4070
"POST /sign-up HTTP/1.1" 200 4080
"POST /sign-up HTTP/1.1" 302 0
"GET /home HTTP/1.1" 200 2000
"GET /summit/list/ HTTP/1.1" 200 3316
"POST /summit/1/delete/ HTTP/1.1" 302 0
"GET /summit/list/ HTTP/1.1" 200 2762
"GET /summit/2/update/ HTTP/1.1" 200 3537
